Workbook
Name Salary: Data!$K$2:$K$514

Sheet Data
A1: Player | B1: Age | C1: Conf | D1: Pos | E1: eFG% | F1: TRB | G1: STL | H1: BLK | I1: PTS | J1: Player-additional | K1: SalaryUSD | L1: AstTovRatio
A2: Steven Adams | B2: 27 | C2: West | D2: Center | E2: 0.614 | F2: 514 | G2: 54 | H2: 38 | I2: 438 | J2: adamsst01 | K2: 29592696 | L2: 1.4230769
A3: Nikola Jokić | B3: 25 | C3: West | D3: Center | E3: 0.602 | F3: 780 | G3: 95 | H3: 48 | I3: 1898 | J3: jokicni01 | K3: 29542010 | L3: 2.6981982
A4: Kristaps Porziņģis | B4: 25 | C4: West | D4: Center | E4: 0.547 | F4: 381 | G4: 20 | H4: 58 | I4: 865 | J4: porzikr01 | K4: 29467800 | L4: 1.3333333
A5: Karl-Anthony Towns | B5: 25 | C5: West | D5: Center | E5: 0.555 | F5: 529 | G5: 39 | H5: 57 | I5: 1239 | J5: townska01 | K5: 29467800 | L5: 1.40625
A6: Rudy Gobert | B6: 28 | C6: West | D6: Center | E6: 0.675 | F6: 960 | G6: 40 | H6: 190 | I6: 1015 | J6: goberru01 | K6: 27525281 | L6: 0.75423729
A7: Al Horford | B7: 34 | C7: West | D7: Center | E7: 0.528 | F7: 188 | G7: 25 | H7: 26 | I7: 398 | J7: horfoal01 | K7: 27500000 | L7: 3.2413793
A8: Jonas Valančiūnas | B8: 28 | C8: West | D8: Center | E8: 0.606 | F8: 776 | G8: 35 | H8: 57 | I8: 1058 | J8: valanjo01 | K8: 15000000 | L8: 1.12
A9: Christian Wood | B9: 25 | C9: West | D9: Center | E9: 0.574 | F9: 395 | G9: 34 | H9: 48 | I9: 860 | J9: woodch01 | K9: 13015873 | L9: 0.8875
A10: Jusuf Nurkić | B10: 26 | C10: West | D10: Center | E10: 0.532 | F10: 332 | G10: 38 | H10: 39 | I10: 424 | J10: nurkiju01 | K10: 12888889 | L10: 1.7123288
A11: Dwight Powell | B11: 29 | C11: West | D11: Center | E11: 0.631 | F11: 234 | G11: 36 | H11: 30 | I11: 342 | J11: poweldw01 | K11: 11080125 | L11: 1.575
A12: Deandre Ayton | B12: 22 | C12: West | D12: Center | E12: 0.629 | F12: 727 | G12: 41 | H12: 81 | I12: 997 | J12: aytonde01 | K12: 9562920 | L12: 0.96116505
A13: Derrick Favors | B13: 29 | C13: West | D13: Center | E13: 0.638 | F13: 376 | G13: 32 | H13: 68 | I13: 369 | J13: favorde01 | K13: 9258000 | L13: 1.2222222
... A514: Elijah Bryant | B514: 25 | C514: East | D514: Guard | E514: 0.5 | F514: 6 | G514: 0 | H514: 1 | I514: 16 | J514: bryanel01 | K514: 24611 | L514: 0.75

Sheet Descriptive Statistics
B2: Continuous Variable | C2: Count | D2: Mean | E2: Median | F2: Standard Dev. | G2: Minimum | H2: Maximum | I2: Range | L2: Categorical Variable | M2: Count | N2: Mode | O2: Number of Unique Categories
B3: Age | C3: =COUNT(Data!B2:B514) -> 513 | D3: =AVERAGE(Data!B2:B514) -> 25.623782 | E3: =MEDIAN(Data!B2:B514) -> 25 | F3: =_xlfn.STDEV.S(Data!B2:B514) -> 4.1293514 | G3: =MIN(Data!B2:B514) -> 19 | H3: =MAX(Data!B2:B514) -> 40 | I3: =H3-G3 -> 21 | L3: Conference | M3: =COUNTA(Data!C2:C514) -> 513 | N3: 220 (West) | O3: 3 (West, East, Multiple Teams)
B4: Effective Field Goal % | C4: =COUNT(Data!E2:E514) -> 513 | D4: =AVERAGE(Data!E2:E514) -> 0.51961404 | E4: =MEDIAN(Data!E2:E514) -> 0.527 | F4: =_xlfn.STDEV.S(Data!E2:E514) -> 0.099336211 | G4: =MIN(Data!E2:E514) -> 0 | H4: =MAX(Data!E2:E514) -> 1 | I4: =H4-G4 -> 1 | L4: Position | M4: =COUNTA(Data!D2:D514) -> 513 | N4: 219 (Guard) | O4: 3 (Guard, Forward, Center)
B5: Total Rebounds | C5: =COUNT(Data!F2:F514) -> 513 | D5: =AVERAGE(Data!F2:F514) -> 185.74464 | E5: =MEDIAN(Data!F2:F514) -> 152 | F5: =_xlfn.STDEV.S(Data!F2:F514) -> 160.0956 | G5: =MIN(Data!F2:F514) -> 1 | H5: =MAX(Data!F2:F514) -> 960 | I5: =H5-G5 -> 959
B6: Steals | C6: =COUNT(Data!G2:G514) -> 513 | D6: =AVERAGE(Data!G2:G514) -> 31.775828 | E6: =MEDIAN(Data!G2:G514) -> 29 | F6: =_xlfn.STDEV.S(Data!G2:G514) -> 24.92564 | G6: =MIN(Data!G2:G514) -> 0 | H6: =MAX(Data!G2:G514) -> 128 | I6: =H6-G6 -> 128
B7: Blocks | C7: =COUNT(Data!H2:H514) -> 513 | D7: =AVERAGE(Data!H2:H514) -> 20.411306 | E7: =MEDIAN(Data!H2:H514) -> 13 | F7: =_xlfn.STDEV.S(Data!H2:H514) -> 23.509482 | G7: =MIN(Data!H2:H514) -> 0 | H7: =MAX(Data!H2:H514) -> 190 | I7: =H7-G7 -> 190
B8: Points | C8: =COUNT(Data!I2:I514) -> 513 | D8: =AVERAGE(Data!I2:I514) -> 470.38402 | E8: =MEDIAN(Data!I2:I514) -> 366 | F8: =_xlfn.STDEV.S(Data!I2:I514) -> 415.76681 | G8: =MIN(Data!I2:I514) -> 0 | H8: =MAX(Data!I2:I514) -> 2015 | I8: =H8-G8 -> 2015
B9: Salary (USD) | C9: =COUNT(Data!K2:K514) -> 513 | D9: =AVERAGE(Data!K2:K514) -> 7027350.8 | E9: =MEDIAN(Data!K2:K514) -> 3044160 | F9: =_xlfn.STDEV.S(Data!K2:K514) -> 9051601 | G9: =MIN(Data!K2:K514) -> 11898 | H9: =MAX(Data!K2:K514) -> 43006362 | I9: =H9-G9 -> 42994464
B10: Assist to Turnover Ratio | C10: =COUNT(Data!L2:L514) -> 513 | D10: =AVERAGE(Data!L2:L514) -> 1.7742005 | E10: =MEDIAN(Data!L2:L514) -> 1.6818182 | F10: =_xlfn.STDEV.S(Data!L2:L514) -> 0.95928635 | G10: =MIN(Data!L2:L514) -> 0 | H10: =MAX(Data!L2:L514) -> 9.6666667 | I10: =H10-G10 -> 9.6666667

Sheet Frequency Tables
B2: Conference | C2: Frequency | D2: Rel. Frequency | K2: Position | L2: Frequency | M2: Rel. Frequency
B3: East | C3: 216 | D3: 0.42105263 | K3: Center | L3: 95 | M3: 0.18518519
B4: Multiple Teams | C4: 77 | D4: 0.15009747 | K4: Forward | L4: 199 | M4: 0.38791423
B5: West | C5: 220 | D5: 0.4288499 | K5: Guard | L5: 219 | M5: 0.42690058
B6: Grand Total | C6: 513 | D6: 1 | K6: Grand Total | L6: 513 | M6: 1
B8: This table reveals that our 513 NBA players are roughly evenly split between the Eastern and Western Conferences. | K8: This table shows that around 43% of players in these data are guards.
B9: Around 42% of players in the dataset are in the East, and the same goes for the West. | K9: Around 39% of players are forwards.
B10: This table also tells us that 15% of players played for multiple teams in the 2020-21 season. | K10: Around 18% of players are centers.
B11: In other words, 85% of players remained on the same team from start to finish in the 2020-21 season. | K11: Overall, guards are the most common players in this dataset, with forwards shortly behind, and centers lagging much further behind.

Sheet Visuals
B2: Row Labels | C2: Count of Age
B3: 19 | C3: 13
B4: 20 | C4: 29
B5: 21 | C5: 44
B6: 22 | C6: 49
B7: 23 | C7: 53
B8: 24 | C8: 47
B9: 25 | C9: 46
B10: 26 | C10: 37
B11: 27 | C11: 35
B12: 28 | C12: 38
B13: 29 | C13: 23
B14: 30 | C14: 27
... B22: 40 | C22: 1
B23: Grand Total | C23: 513
B25: Row Labels | C25: Count of SalaryUSD
B26: >$5 | C26: 320
B27: $5-10 | C27: 78
B28: $10-15 | C28: 39
B29: $15-20 | C29: 27
B30: $20-25 | C30: 8
B31: $25-30 | C31: 20
B32: $30-35 | C32: 13
B33: $35-40 | C33: 2
B34: $40-45 | C34: 6
B35: Grand Total | C35: 513
B43: Row Labels | C43: Count of Conf
B44: East | C44: 216
B45: Multiple Teams | C45: 77
B46: West | C46: 220
B47: Grand Total | C47: 513
B60: Row Labels | C60: Count of Pos
B61: Guard | C61: 219
B62: Forward | C62: 199
B63: Center | C63: 94
B64: Grand Total | C64: 512
B76: Row Labels | C76: Average of AstTovRatio
B77: Guard | C77: 2.1967188
B78: Forward | C78: 1.5512978
B79: Center | C79: 1.267107
...

Sheet Commentary
A1: Ideas:
A2: How well do variables correlate to salary from the scatter plots?
A3: Many more young players from the age histogram
A4: Block and steal boxplots tell us that many players don't rack up defensive stats, so maybe defensive stats are really valuable
A5: Blocks especially have a number of points outside the upper whisker of the boxplot.
A6: Many players have low stat totals, showing the majority of the league simply doesn't get much playing time
A7: Majority of players make below $5 million
A8: Conferences are pretty evenly split, much less players played for multiple teams but still a decent amount
A9: Most popular position is guard, then forward, then center
A10: Guards tend to have better assist to turnover ratios (in other words, guards are better passers - probably other skills that correlate to different position like blocks/rebounds for centers or shooting for guards/forwards)
A13: The dataset covers 513 NBA players from the 2020–21 season across 12 columns. We removed several fields from the raw export and retained the core box-score measures, including points, rebounds, and blocks. We also added two advanced measures, effective field goal percentage and assist-to-turnover ratio, to better represent player performance. Categorical variables were recoded using find and replace: position was collapsed from the five conventional designations (PG, SG, SF, PF, C) into three — Guard, Forward, and Center — and team was generalized to conference — East, West, and Multiple Teams for players traded mid-season. What the descriptive statistics reveal most clearly is that almost every continuous variable is right-skewed. Salary is the extreme case: the mean of $7.03M sits more than double the median of $3.04M, 62% of the league earns under $5 million, and the range spans from $11,898 to $43.0M — a factor of over 3,600. Blocks are similarly lopsided (mean 20.4, median 13, 27 values flagged as statistical outliers by the 1.5×IQR rule), which is why the boxplot shows so many points above the upper whisker. These aren't data-entry errors; they reflect a genuine feature of the league, where a small number of stars accumulate most of the production and most of the payroll while the majority of rostered players see limited minutes. The one place we'd caution against reading the numbers literally is effective field goal percentage, where the min of 0.000 and max of 1.000 come from players with a handful of total attempts — small-sample artifacts rather than meaningful shooting ability.
A15: The categorical variables are more balanced than the continuous ones. Conference splits almost evenly (West 42.9%, East 42.1%), which is reassuring — it means conference comparisons won't be distorted by unequal group sizes — while 15% of players changed teams during the season, a higher churn rate than we expected. Position is moderately unbalanced: guards (42.7%) and forwards (38.8%) together account for over 80% of the league, with centers at just 18.5%, consistent with the modern shift toward smaller, perimeter-oriented lineups. The clearest positional pattern is in assist-to-turnover ratio, where guards average 2.20 against forwards at 1.55 and centers at 1.27 — a large and intuitive gap, since guards handle the ball as their primary job. Looking at the scatterplots against salary, points scored shows the strongest visible relationship, and the correlations bear that out: PTS at r = 0.65, followed by steals (0.49), rebounds (0.46), age (0.37), blocks (0.27), and then a steep drop to assist-to-turnover ratio (0.15) and eFG% (0.14). That last result is what we'd most want to explore next — if efficiency barely correlates with pay while raw scoring volume correlates strongly, teams may be paying for counting stats rather than for how effectively those stats are produced. Three follow-up questions we'd pursue: (1) does the relationship hold once you control for minutes played, since volume stats and salary may both simply be proxies for playing time? (2) does age interact with salary non-linearly — rookie-scale contracts should compress young players' pay regardless of production, which would show up as a curve rather than a line; and (3) are the ~48 salary outliers above the IQR fence a distinct "max contract" tier that should be modeled separately rather than pooled with the rest of the league?
