Workbook
Name Salary: Data!$F$2:$F$514

Sheet Data
A1: Player | B1: Pos | C1: Conf | D1: Age | E1: PTS | F1: SalaryUSD | G1: Player-additional | H1: Pos_Forward | I1: STL | J1: AstTovRatio | K1: Conf_East | L1: Conf_West | M1: BLK | N1: TRB | O1: Pos_Guard | P1: eFG
A2: Steven Adams | B2: Center | C2: West | D2: 27 | E2: 438 | F2: 29592696 | G2: adamsst01 | H2: =IF(B2="Forward", 1, 0) -> 0 | I2: 54 | J2: 1.4230769 | K2: =IF(C2="East", 1, 0) -> 0 | L2: =IF(C2="West", 1, 0) -> 1 | M2: 38 | N2: 514 | O2: =IF($B2="Guard", 1, 0) -> 0 | P2: 0.614
A3: Nikola Jokić | B3: Center | C3: West | D3: 25 | E3: 1898 | F3: 29542010 | G3: jokicni01 | H3: =IF(B3="Forward", 1, 0) -> 0 | I3: 95 | J3: 2.6981982 | K3: =IF(C3="East", 1, 0) -> 0 | L3: =IF(C3="West", 1, 0) -> 1 | M3: 48 | N3: 780 | O3: =IF($B3="Guard", 1, 0) -> 0 | P3: 0.602
A4: Kristaps Porziņģis | B4: Center | C4: West | D4: 25 | E4: 865 | F4: 29467800 | G4: porzikr01 | H4: =IF(B4="Forward", 1, 0) -> 0 | I4: 20 | J4: 1.3333333 | K4: =IF(C4="East", 1, 0) -> 0 | L4: =IF(C4="West", 1, 0) -> 1 | M4: 58 | N4: 381 | O4: =IF($B4="Guard", 1, 0) -> 0 | P4: 0.547
A5: Karl-Anthony Towns | B5: Center | C5: West | D5: 25 | E5: 1239 | F5: 29467800 | G5: townska01 | H5: =IF(B5="Forward", 1, 0) -> 0 | I5: 39 | J5: 1.40625 | K5: =IF(C5="East", 1, 0) -> 0 | L5: =IF(C5="West", 1, 0) -> 1 | M5: 57 | N5: 529 | O5: =IF($B5="Guard", 1, 0) -> 0 | P5: 0.555
A6: Rudy Gobert | B6: Center | C6: West | D6: 28 | E6: 1015 | F6: 27525281 | G6: goberru01 | H6: =IF(B6="Forward", 1, 0) -> 0 | I6: 40 | J6: 0.75423729 | K6: =IF(C6="East", 1, 0) -> 0 | L6: =IF(C6="West", 1, 0) -> 1 | M6: 190 | N6: 960 | O6: =IF($B6="Guard", 1, 0) -> 0 | P6: 0.675
A7: Al Horford | B7: Center | C7: West | D7: 34 | E7: 398 | F7: 27500000 | G7: horfoal01 | H7: =IF(B7="Forward", 1, 0) -> 0 | I7: 25 | J7: 3.2413793 | K7: =IF(C7="East", 1, 0) -> 0 | L7: =IF(C7="West", 1, 0) -> 1 | M7: 26 | N7: 188 | O7: =IF($B7="Guard", 1, 0) -> 0 | P7: 0.528
A8: Jonas Valančiūnas | B8: Center | C8: West | D8: 28 | E8: 1058 | F8: 15000000 | G8: valanjo01 | H8: =IF(B8="Forward", 1, 0) -> 0 | I8: 35 | J8: 1.12 | K8: =IF(C8="East", 1, 0) -> 0 | L8: =IF(C8="West", 1, 0) -> 1 | M8: 57 | N8: 776 | O8: =IF($B8="Guard", 1, 0) -> 0 | P8: 0.606
A9: Christian Wood | B9: Center | C9: West | D9: 25 | E9: 860 | F9: 13015873 | G9: woodch01 | H9: =IF(B9="Forward", 1, 0) -> 0 | I9: 34 | J9: 0.8875 | K9: =IF(C9="East", 1, 0) -> 0 | L9: =IF(C9="West", 1, 0) -> 1 | M9: 48 | N9: 395 | O9: =IF($B9="Guard", 1, 0) -> 0 | P9: 0.574
A10: Jusuf Nurkić | B10: Center | C10: West | D10: 26 | E10: 424 | F10: 12888889 | G10: nurkiju01 | H10: =IF(B10="Forward", 1, 0) -> 0 | I10: 38 | J10: 1.7123288 | K10: =IF(C10="East", 1, 0) -> 0 | L10: =IF(C10="West", 1, 0) -> 1 | M10: 39 | N10: 332 | O10: =IF($B10="Guard", 1, 0) -> 0 | P10: 0.532
A11: Dwight Powell | B11: Center | C11: West | D11: 29 | E11: 342 | F11: 11080125 | G11: poweldw01 | H11: =IF(B11="Forward", 1, 0) -> 0 | I11: 36 | J11: 1.575 | K11: =IF(C11="East", 1, 0) -> 0 | L11: =IF(C11="West", 1, 0) -> 1 | M11: 30 | N11: 234 | O11: =IF($B11="Guard", 1, 0) -> 0 | P11: 0.631
A12: Deandre Ayton | B12: Center | C12: West | D12: 22 | E12: 997 | F12: 9562920 | G12: aytonde01 | H12: =IF(B12="Forward", 1, 0) -> 0 | I12: 41 | J12: 0.96116505 | K12: =IF(C12="East", 1, 0) -> 0 | L12: =IF(C12="West", 1, 0) -> 1 | M12: 81 | N12: 727 | O12: =IF($B12="Guard", 1, 0) -> 0 | P12: 0.629
A13: Derrick Favors | B13: Center | C13: West | D13: 29 | E13: 369 | F13: 9258000 | G13: favorde01 | H13: =IF(B13="Forward", 1, 0) -> 0 | I13: 32 | J13: 1.2222222 | K13: =IF(C13="East", 1, 0) -> 0 | L13: =IF(C13="West", 1, 0) -> 1 | M13: 68 | N13: 376 | O13: =IF($B13="Guard", 1, 0) -> 0 | P13: 0.638
... A514: Elijah Bryant | B514: Guard | C514: East | D514: 25 | E514: 16 | F514: 24611 | G514: bryanel01 | H514: =IF(B514="Forward", 1, 0) -> 0 | I514: 0 | J514: 0.75 | K514: =IF(C514="East", 1, 0) -> 1 | L514: =IF(C514="West", 1, 0) -> 0 | M514: 1 | N514: 6 | O514: =IF($B514="Guard", 1, 0) -> 1 | P514: 0.5

Sheet Model 1 - All Variables
A1: SUMMARY OUTPUT
A3: Regression Statistics
A4: Multiple R | B4: 0.71512318
A5: R Square | B5: 0.51140116
A6: Adjusted R Square | B6: 0.50067344
A7: Standard Error | B7: 6396136.6
A8: Observations | B8: 513
A10: ANOVA
B11: df | C11: SS | D11: MS | E11: F | F11: Significance F
A12: Regression | B12: 11 | C12: 2.1452726e+16 | D12: 1.9502478e+15 | E12: 47.671007 | F12: 7.5259502e-71
A13: Residual | B13: 501 | C13: 2.0496193e+16 | D13: 4.0910564e+13
A14: Total | B14: 512 | C14: 4.1948918e+16
B16: Coefficients | C16: Standard Error | D16: t Stat | E16: P-value | F16: Lower 95% | G16: Upper 95% | H16: Lower 95.0% | I16: Upper 95.0%
A17: Intercept | B17: -12990879 | C17: 2625691.8 | D17: -4.9476022 | E17: 1.027554e-06 | F17: -18149602 | G17: -7832154.7 | H17: -18149602 | I17: -7832154.7
A18: Conf_West | B18: 909917.46 | C18: 867748.75 | D18: 1.0485955 | E18: 0.29486989 | F18: -794957.46 | G18: 2614792.4 | H18: -794957.46 | I18: 2614792.4
A19: Conf_East | B19: 709240.76 | C19: 863432.05 | D19: 0.82142046 | E19: 0.41179752 | F19: -987153.11 | G19: 2405634.6 | H19: -987153.11 | I19: 2405634.6
A20: Pos_Guard | B20: -962087.03 | C20: 1135611.2 | D20: -0.84719756 | E20: 0.39728953 | F20: -3193234.1 | G20: 1269060 | H20: -3193234.1 | I20: 1269060
A21: Pos_Forward | B21: -70622.782 | C21: 960431.67 | D21: -0.073532334 | E21: 0.94141186 | F21: -1957592.8 | G21: 1816347.2 | H21: -1957592.8 | I21: 1816347.2
A22: Age | B22: 656218.24 | C22: 73048.395 | D22: 8.9833355 | E22: 5.3417975e-18 | F22: 512699.3 | G22: 799737.18 | H22: 512699.3 | I22: 799737.18
A23: eFG | B23: -7479852.8 | C23: 3133742.2 | D23: -2.3868756 | E23: 0.01736226 | F23: -13636748 | G23: -1322957.1 | H23: -13636748 | I23: -1322957.1
A24: TRB | B24: -4118.0036 | C24: 3779.2336 | D24: -1.0896399 | E24: 0.27639563 | F24: -11543.103 | G24: 3307.0956 | H24: -11543.103 | I24: 3307.0956
A25: STL | B25: -8677.3253 | C25: 19636.276 | D25: -0.44190279 | E25: 0.65875023 | F25: -47256.92 | G25: 29902.269 | H25: -47256.92 | I25: 29902.269
A26: BLK | B26: 19623.079 | C26: 19401.628 | D26: 1.011414 | E26: 0.31230652 | F26: -18495.5 | G26: 57741.657 | H26: -18495.5 | I26: 57741.657
A27: PTS | B27: 14774.026 | C27: 1256.5188 | D27: 11.757903 | E27: 2.3461681e-28 | F27: 12305.33 | G27: 17242.721 | H27: 12305.33 | I27: 17242.721
A28: AstTovRatio | B28: 298707.2 | C28: 345887.39 | D28: 0.86359669 | E28: 0.38822273 | F28: -380861.32 | G28: 978275.73 | H28: -380861.32 | I28: 978275.73
A30: Interpretations:
A31: R-squared = | B31: =B5 -> 0.51140116 | D31: Based on the r-squared value, this model explains 51.14% of the variation in player salary.
A32: Adj. R-squared = | B32: =B6 -> 0.50067344 | D32: Based on the adjusted r-squared value, this model explains 50.07% of the variation in player salary.
A34: Using a 0.05 significance level (a = 0.05), the following predictors are significant (i.e. p-value < a):
A35: Intercept
A36: Age
A37: Effective Field Goal %
A38: Points
A40: At the 0.05 significance level, the following predictors are insignificant (i.e. p-value > a):
A41: Conference = West
A42: Conference = East
A43: Position = Guard
A44: Position = Forward
A45: Total Rebounds
A46: Steals
...

Sheet Model 2
A1: Predictor Removed: Position = Forward
A2: This predictor's p-value was the highest (0.941)
A4: SUMMARY OUTPUT
A6: Regression Statistics
A7: Multiple R | B7: 0.71511949
A8: R Square | B8: 0.51139589
A9: Adjusted R Square | B9: 0.50166274
A10: Standard Error | B10: 6389797.3
A11: Observations | B11: 513
A13: ANOVA
B14: df | C14: SS | D14: MS | E14: F | F14: Significance F
A15: Regression | B15: 10 | C15: 2.1452504e+16 | D15: 2.1452504e+15 | E15: 52.541666 | F15: 1.0128836e-71
A16: Residual | B16: 502 | C16: 2.0496414e+16 | D16: 4.082951e+13
A17: Total | B17: 512 | C17: 4.1948918e+16
B19: Coefficients | C19: Standard Error | D19: t Stat | E19: P-value | F19: Lower 95% | G19: Upper 95% | H19: Lower 95.0% | I19: Upper 95.0%
A20: Intercept | B20: -13065099 | C20: 2421531.7 | D20: -5.3953863 | E20: 1.0555139e-07 | F20: -17822684 | G20: -8307513.6 | H20: -17822684 | I20: -8307513.6
A21: Conf_West | B21: 905681.87 | C21: 864976.67 | D21: 1.0470593 | E21: 0.2955761 | F21: -793738.52 | G21: 2605102.3 | H21: -793738.52 | I21: 2605102.3
A22: Conf_East | B22: 705939.66 | C22: 861409.57 | D22: 0.81951685 | E22: 0.4128805 | F22: -986472.45 | G22: 2398351.8 | H22: -986472.45 | I22: 2398351.8
A23: Pos_Guard | B23: -897010.79 | C23: 710901.89 | D23: -1.2617927 | E23: 0.20760936 | F23: -2293720.3 | G23: 499698.75 | H23: -2293720.3 | I23: 499698.75
A24: Age | B24: 656643.54 | C24: 72746.88 | D24: 9.0264151 | E24: 3.7891388e-18 | F24: 513717.69 | G24: 799569.4 | H24: 513717.69 | I24: 799569.4
A25: eFG | B25: -7458073.5 | C25: 3116621.8 | D25: -2.3929993 | E25: 0.017077739 | F25: -13581303 | G25: -1334844.1 | H25: -13581303 | I25: -1334844.1
A26: TRB | B26: -4058.0462 | C26: 3686.5658 | D26: -1.100766 | E26: 0.27152606 | F26: -11301.045 | G26: 3184.9527 | H26: -11301.045 | I26: 3184.9527
A27: STL | B27: -9104.9358 | C27: 18736.836 | D27: -0.48593775 | E27: 0.62722334 | F27: -45917.213 | G27: 27707.341 | H27: -45917.213 | I27: 27707.341
A28: BLK | B28: 20067.249 | C28: 18419.074 | D28: 1.089482 | E28: 0.27646412 | F28: -16120.722 | G28: 56255.22 | H28: -16120.722 | I28: 56255.22
A29: PTS | B29: 14763.518 | C29: 1247.1295 | D29: 11.837999 | E29: 1.0983652e-28 | F29: 12313.282 | G29: 17213.754 | H29: 12313.282 | I29: 17213.754
A30: AstTovRatio | B30: 297784.42 | C30: 345317.07 | D30: 0.86235071 | E30: 0.38890632 | F30: -380660.31 | G30: 976229.15 | H30: -380660.31 | I30: 976229.15

Sheet Model 3
A1: Predictor Removed: Steals
A2: This predictor's p-value was the highest (0.627)
A4: SUMMARY OUTPUT
A6: Regression Statistics
A7: Multiple R | B7: 0.71495878
A8: R Square | B8: 0.51116606
A9: Adjusted R Square | B9: 0.50241952
A10: Standard Error | B10: 6384943.6
A11: Observations | B11: 513
A13: ANOVA
B14: df | C14: SS | D14: MS | E14: F | F14: Significance F
A15: Regression | B15: 9 | C15: 2.1442863e+16 | D15: 2.3825403e+15 | E15: 58.442142 | F15: 1.4440645e-72
A16: Residual | B16: 503 | C16: 2.0506055e+16 | D16: 4.0767505e+13
A17: Total | B17: 512 | C17: 4.1948918e+16
B19: Coefficients | C19: Standard Error | D19: t Stat | E19: P-value | F19: Lower 95% | G19: Upper 95% | H19: Lower 95.0% | I19: Upper 95.0%
A20: Intercept | B20: -13004875 | C20: 2416521.1 | D20: -5.3816515 | E20: 1.1336315e-07 | F20: -17752593 | G20: -8257156.2 | H20: -17752593 | I20: -8257156.2
A21: Conf_West | B21: 917222.77 | C21: 863993.77 | D21: 1.0616081 | E21: 0.28892308 | F21: -780258.37 | G21: 2614703.9 | H21: -780258.37 | I21: 2614703.9
A22: Conf_East | B22: 705163.01 | C22: 860753.77 | D22: 0.81923895 | E22: 0.41303808 | F22: -985952.51 | G22: 2396278.5 | H22: -985952.51 | I22: 2396278.5
A23: Pos_Guard | B23: -943630.92 | C23: 703863.48 | D23: -1.3406448 | E23: 0.18064095 | F23: -2326505.4 | G23: 439243.61 | H23: -2326505.4 | I23: 439243.61
A24: Age | B24: 654801.2 | C24: 72592.834 | D24: 9.0201905 | E24: 3.9572448e-18 | F24: 512178.68 | G24: 797423.71 | H24: 512178.68 | I24: 797423.71
A25: eFG | B25: -7451386 | C25: 3114224 | D25: -2.3926943 | E25: 0.017091043 | F25: -13569875 | G25: -1332896.9 | H25: -13569875 | I25: -1332896.9
A26: TRB | B26: -4340.9726 | C26: 3637.534 | D26: -1.1933834 | E26: 0.23328182 | F26: -11487.604 | G26: 2805.6592 | H26: -11487.604 | I26: 2805.6592
A27: BLK | B27: 19023.092 | C27: 18279.414 | D27: 1.0406839 | E27: 0.29852223 | F27: -16890.316 | G27: 54936.501 | H27: -16890.316 | I27: 54936.501
A28: PTS | B28: 14477.439 | C28: 1098.5944 | D28: 13.178147 | E28: 2.8145415e-34 | F28: 12319.04 | G28: 16635.838 | H28: 12319.04 | I28: 16635.838
A29: AstTovRatio | B29: 251511.99 | C29: 331676.27 | D29: 0.75830565 | E29: 0.44862317 | F29: -400129.53 | G29: 903153.52 | H29: -400129.53 | I29: 903153.52

Sheet Model 4
A1: Predictor Removed: Assist to Turnover Ratio
A2: This predictor's p-value was the highest (0.449)
A4: SUMMARY OUTPUT
A6: Regression Statistics
A7: Multiple R | B7: 0.71456786
A8: R Square | B8: 0.51060722
A9: Adjusted R Square | B9: 0.50283908
A10: Standard Error | B10: 6382251.2
A11: Observations | B11: 513
A13: ANOVA
B14: df | C14: SS | D14: MS | E14: F | F14: Significance F
A15: Regression | B15: 8 | C15: 2.1419421e+16 | D15: 2.6774276e+15 | E15: 65.730956 | F15: 2.2869294e-73
A16: Residual | B16: 504 | C16: 2.0529498e+16 | D16: 4.073313e+13
A17: Total | B17: 512 | C17: 4.1948918e+16
B19: Coefficients | C19: Standard Error | D19: t Stat | E19: P-value | F19: Lower 95% | G19: Upper 95% | H19: Lower 95.0% | I19: Upper 95.0%
A20: Intercept | B20: -12984929 | C20: 2415359 | D20: -5.3759831 | E20: 1.1669268e-07 | F20: -17730342 | G20: -8239516.8 | H20: -17730342 | I20: -8239516.8
A21: Conf_West | B21: 944219.11 | C21: 862895.97 | D21: 1.0942444 | E21: 0.27437047 | F21: -751097.07 | G21: 2639535.3 | H21: -751097.07 | I21: 2639535.3
A22: Conf_East | B22: 689438.42 | C22: 860141.08 | D22: 0.80154109 | E22: 0.42319619 | F22: -1000465.3 | G22: 2379342.1 | H22: -1000465.3 | I22: 2379342.1
A23: Pos_Guard | B23: -756156.45 | C23: 658738.08 | D23: -1.1478864 | E23: 0.25156004 | F23: -2050367.3 | G23: 538054.4 | H23: -2050367.3 | I23: 538054.4
A24: Age | B24: 667402.22 | C24: 70635.494 | D24: 9.4485389 | E24: 1.2854247e-19 | F24: 528625.93 | G24: 806178.5 | H24: 528625.93 | I24: 806178.5
A25: eFG | B25: -7438279 | C25: 3112862.8 | D25: -2.38953 | E25: 0.017236541 | F25: -13554065 | G25: -1322493.4 | H25: -13554065 | I25: -1322493.4
A26: TRB | B26: -4144.1664 | C26: 3626.7335 | D26: -1.1426719 | E26: 0.25371737 | F26: -11269.544 | G26: 2981.2116 | H26: -11269.544 | I26: 2981.2116
A27: BLK | B27: 17572.78 | C27: 18171.417 | D27: 0.96705608 | E27: 0.33397981 | F27: -18128.277 | G27: 53273.836 | H27: -18128.277 | I27: 53273.836
A28: PTS | B28: 14487.321 | C28: 1098.0539 | D28: 13.193634 | E28: 2.3676932e-34 | F28: 12329.995 | G28: 16644.648 | H28: 12329.995 | I28: 16644.648

Sheet Model 5
A1: Predictor Removed: Conference = East
A2: This predictor's p-value was the highest (0.423)
A4: SUMMARY OUTPUT
A6: Regression Statistics
A7: Multiple R | B7: 0.7141312
A8: R Square | B8: 0.50998338
A9: Adjusted R Square | B9: 0.50319107
A10: Standard Error | B10: 6379991.5
A11: Observations | B11: 513
A13: ANOVA
B14: df | C14: SS | D14: MS | E14: F | F14: Significance F
A15: Regression | B15: 7 | C15: 2.1393251e+16 | D15: 3.0561787e+15 | E15: 75.082469 | F15: 3.4898936e-74
A16: Residual | B16: 505 | C16: 2.0555667e+16 | D16: 4.0704292e+13
A17: Total | B17: 512 | C17: 4.1948918e+16
B19: Coefficients | C19: Standard Error | D19: t Stat | E19: P-value | F19: Lower 95% | G19: Upper 95% | H19: Lower 95.0% | I19: Upper 95.0%
A20: Intercept | B20: -12332979 | C20: 2273483.2 | D20: -5.4247067 | E20: 9.0194882e-08 | F20: -16799630 | G20: -7866329.2 | H20: -16799630 | I20: -7866329.2
A21: Conf_West | B21: 428032.7 | C21: 574133.82 | D21: 0.74552776 | E21: 0.45629959 | F21: -699952.3 | G21: 1556017.7 | H21: -699952.3 | I21: 1556017.7
A22: Pos_Guard | B22: -732546.8 | C22: 657846.21 | D22: -1.1135533 | E22: 0.26600061 | F22: -2024999.2 | G22: 559905.64 | H22: -2024999.2 | I22: 559905.64
A23: Age | B23: 659276.47 | C23: 69879.476 | D23: 9.4344792 | E23: 1.4314868e-19 | F23: 521986.17 | G23: 796566.76 | H23: 521986.17 | I23: 796566.76
A24: eFG | B24: -7372025.8 | C24: 3110663.5 | D24: -2.3699207 | E24: 0.018166739 | F24: -13483461 | G24: -1260590.4 | H24: -13483461 | I24: -1260590.4
A25: TRB | B25: -4127.3438 | C25: 3625.3887 | D25: -1.1384555 | E25: 0.2554701 | F25: -11250.046 | G25: 2995.3581 | H25: -11250.046 | I25: 2995.3581
A26: BLK | B26: 17493.36 | C26: 18164.714 | D26: 0.96304077 | E26: 0.33598797 | F26: -18194.356 | G26: 53181.076 | H26: -18194.356 | I26: 53181.076
A27: PTS | B27: 14533.901 | C27: 1096.1268 | D27: 13.259324 | E27: 1.2126171e-34 | F27: 12380.37 | G27: 16687.431 | H27: 12380.37 | I27: 16687.431

Sheet Model 6
A1: Predictor Removed: Conference = West
A2: This predictor's p-value was the highest (0.456)
A4: SUMMARY OUTPUT
A6: Regression Statistics
A7: Multiple R | B7: 0.7137535
A8: R Square | B8: 0.50944406
A9: Adjusted R Square | B9: 0.50362719
A10: Standard Error | B10: 6377190.6
A11: Observations | B11: 513
A13: ANOVA
B14: df | C14: SS | D14: MS | E14: F | F14: Significance F
A15: Regression | B15: 6 | C15: 2.1370627e+16 | D15: 3.5617712e+15 | E15: 87.58046 | F15: 4.6992776e-75
A16: Residual | B16: 506 | C16: 2.0578291e+16 | D16: 4.066856e+13
A17: Total | B17: 512 | C17: 4.1948918e+16
B19: Coefficients | C19: Standard Error | D19: t Stat | E19: P-value | F19: Lower 95% | G19: Upper 95% | H19: Lower 95.0% | I19: Upper 95.0%
A20: Intercept | B20: -12088758 | C20: 2248771.5 | D20: -5.3757168 | E20: 1.166661e-07 | F20: -16506837 | G20: -7670679.6 | H20: -16506837 | I20: -7670679.6
A21: Pos_Guard | B21: -752181.06 | C21: 657030.26 | D21: -1.1448195 | E21: 0.25282514 | F21: -2043024.3 | G21: 538662.18 | H21: -2043024.3 | I21: 538662.18
A22: Age | B22: 654405.37 | C22: 69542.808 | D22: 9.4101085 | E22: 1.732957e-19 | F22: 517777.17 | G22: 791033.58 | H22: 517777.17 | I22: 791033.58
A23: eFG | B23: -7263957.1 | C23: 3105920 | D23: -2.3387457 | E23: 0.019736965 | F23: -13366044 | G23: -1161870 | H23: -13366044 | I23: -1161870
A24: TRB | B24: -4101.3777 | C24: 3623.6299 | D24: -1.1318423 | E24: 0.25823682 | F24: -11220.59 | G24: 3017.8349 | H24: -11220.59 | I24: 3017.8349
A25: BLK | B25: 17202.928 | C25: 18152.563 | D25: 0.94768591 | E25: 0.34374174 | F25: -18460.746 | G25: 52866.603 | H25: -18460.746 | I25: 52866.603
A26: PTS | B26: 14571.082 | C26: 1094.5109 | D26: 13.31287 | E26: 6.9903619e-35 | F26: 12420.737 | G26: 16721.428 | H26: 12420.737 | I26: 16721.428

Sheet Model 7
A1: Predictor Removed: Blocks
A2: This predictor's p-value was the highest (0.344)
A4: SUMMARY OUTPUT
A6: Regression Statistics
A7: Multiple R | B7: 0.71314329
A8: R Square | B8: 0.50857336
A9: Adjusted R Square | B9: 0.50372694
A10: Standard Error | B10: 6376549.7
A11: Observations | B11: 513
A13: ANOVA
B14: df | C14: SS | D14: MS | E14: F | F14: Significance F
A15: Regression | B15: 5 | C15: 2.1334102e+16 | D15: 4.2668204e+15 | E15: 104.93802 | F15: 6.7969755e-76
A16: Residual | B16: 507 | C16: 2.0614816e+16 | D16: 4.0660386e+13
A17: Total | B17: 512 | C17: 4.1948918e+16
B19: Coefficients | C19: Standard Error | D19: t Stat | E19: P-value | F19: Lower 95% | G19: Upper 95% | H19: Lower 95.0% | I19: Upper 95.0%
A20: Intercept | B20: -12128104 | C20: 2248162.2 | D20: -5.3946748 | E20: 1.0551125e-07 | F20: -16544965 | G20: -7711243 | H20: -16544965 | I20: -7711243
A21: Pos_Guard | B21: -808295.42 | C21: 654290.95 | D21: -1.2353761 | E21: 0.21726269 | F21: -2093750.8 | G21: 477159.92 | H21: -2093750.8 | I21: 477159.92
A22: Age | B22: 651801.01 | C22: 69481.505 | D22: 9.3809282 | E22: 2.1806306e-19 | F22: 515293.9 | G22: 788308.13 | H22: 515293.9 | I22: 788308.13
A23: eFG | B23: -6903919.1 | C23: 3082287.5 | D23: -2.2398687 | E23: 0.025532036 | F23: -12959548 | G23: -848290.72 | H23: -12959548 | I23: -848290.72
A24: TRB | B24: -2014.9643 | C24: 2877.8535 | D24: -0.7001622 | E24: 0.48414717 | F24: -7668.9508 | G24: 3639.0223 | H24: -7668.9508 | I24: 3639.0223
A25: PTS | B25: 14372.41 | C25: 1074.1385 | D25: 13.380406 | E25: 3.5013671e-35 | F25: 12262.099 | G25: 16482.72 | H25: 12262.099 | I25: 16482.72

Sheet Model 8
A1: Predictor Removed: Total Rebounds
A2: This predictor's p-value was the highest (0.484)
A4: SUMMARY OUTPUT
A6: Regression Statistics
A7: Multiple R | B7: 0.71281007
A8: R Square | B8: 0.50809819
A9: Adjusted R Square | B9: 0.50422495
A10: Standard Error | B10: 6373349.5
A11: Observations | B11: 513
A13: ANOVA
B14: df | C14: SS | D14: MS | E14: F | F14: Significance F
A15: Regression | B15: 4 | C15: 2.1314169e+16 | D15: 5.3285423e+15 | E15: 131.18161 | F15: 7.0999041e-77
A16: Residual | B16: 508 | C16: 2.0634749e+16 | D16: 4.0619584e+13
A17: Total | B17: 512 | C17: 4.1948918e+16
B19: Coefficients | C19: Standard Error | D19: t Stat | E19: P-value | F19: Lower 95% | G19: Upper 95% | H19: Lower 95.0% | I19: Upper 95.0%
A20: Intercept | B20: -12159820 | C20: 2246577.8 | D20: -5.4125967 | E20: 9.5916756e-08 | F20: -16573547 | G20: -7746092.3 | H20: -16573547 | I20: -7746092.3
A21: Pos_Guard | B21: -610481.61 | C21: 589852.85 | D21: -1.0349727 | E21: 0.30117408 | F21: -1769332.9 | G21: 548369.71 | H21: -1769332.9 | I21: 548369.71
A22: Age | B22: 651027.82 | C22: 69437.863 | D22: 9.3756892 | E22: 2.2608712e-19 | F22: 514607.09 | G22: 787448.56 | H22: 514607.09 | I22: 787448.56
A23: eFG | B23: -7179752.8 | C23: 3055473.1 | D23: -2.3498007 | E23: 0.019165256 | F23: -13182672 | G23: -1176833.5 | H23: -13182672 | I23: -1176833.5
A24: PTS | B24: 13811.462 | C24: 715.11465 | D24: 19.313633 | E24: 9.947574e-63 | F24: 12406.516 | G24: 15216.408 | H24: 12406.516 | I24: 15216.408

Sheet Model 9
A1: Predictor Removed: Position = Guard
A2: This predictor's p-value was the highest (0.301)
A4: SUMMARY OUTPUT
A6: Regression Statistics
A7: Multiple R | B7: 0.71208213
A8: R Square | B8: 0.50706097
A9: Adjusted R Square | B9: 0.50415563
A10: Standard Error | B10: 6373795.1
A11: Observations | B11: 513
A13: ANOVA
B14: df | C14: SS | D14: MS | E14: F | F14: Significance F
A15: Regression | B15: 3 | C15: 2.1270659e+16 | D15: 7.0902196e+15 | E15: 174.52735 | F15: 8.4171287e-78
A16: Residual | B16: 509 | C16: 2.0678259e+16 | D16: 4.0625264e+13
A17: Total | B17: 512 | C17: 4.1948918e+16
B19: Coefficients | C19: Standard Error | D19: t Stat | E19: P-value | F19: Lower 95% | G19: Upper 95% | H19: Lower 95.0% | I19: Upper 95.0%
A20: Intercept | B20: -12821995 | C20: 2153698.4 | D20: -5.9534773 | E20: 4.8947158e-09 | F20: -17053227 | G20: -8590762.2 | H20: -17053227 | I20: -8590762.2
A21: Age | B21: 653623.01 | C21: 69397.425 | D21: 9.4185485 | E21: 1.5881594e-19 | F21: 517282.36 | G21: 789963.65 | H21: 517282.36 | I21: 789963.65
A22: eFG | B22: -6425467.6 | C22: 2967490.8 | D22: -2.1652864 | E22: 0.030829616 | F22: -12255506 | G22: -595429.61 | H22: -12255506 | I22: -595429.61
A23: PTS | B23: 13690.549 | C23: 705.55648 | D23: 19.403902 | E23: 3.4016923e-63 | F23: 12304.387 | G23: 15076.71 | H23: 12304.387 | I23: 15076.71

Sheet Final Model
A1: Predictor Removed: Effective Field Goal %
A2: While all the predictors in model 9 had significant p-values, something had to be flagged about the coefficient of effective field goal %.
A3: This metric is essentially a weighted shooting metric - higher values indicate better and more accurate shooters.
A4: However, the extreme negative coefficient would indicate that higher effective field goal percentage lowers average salary, holding all else constant.
A5: This doesn't make sense conceptually, and is likely due to small sample size for some players. Players who played very little and thus attempted
A6: very few shots likely had extremely high effective field goal percentages. All of this is to say, effective field goal % had to be removed
A7: as a predictor, because it simply wouldn't make sense for better shooters to be making less, and including that as a predictor would hurt
A8: the model's predictive accuracy.
A10: SUMMARY OUTPUT
A12: Regression Statistics
A13: Multiple R | B13: 0.70888676
A14: R Square | B14: 0.50252044
A15: Adjusted R Square | B15: 0.50056954
A16: Standard Error | B16: 6396802.1
A17: Observations | B17: 513
A19: ANOVA
B20: df | C20: SS | D20: MS | E20: F | F20: Significance F
A21: Regression | B21: 2 | C21: 2.1080189e+16 | D21: 1.0540094e+16 | E21: 257.58387 | F21: 4.7608731e-78
A22: Residual | B22: 510 | C22: 2.0868729e+16 | D22: 4.0919077e+13
A23: Total | B23: 512 | C23: 4.1948918e+16
B25: Coefficients | C25: Standard Error | D25: t Stat | E25: P-value | F25: Lower 95% | G25: Upper 95% | H25: Lower 95.0% | I25: Upper 95.0%
A26: Intercept | B26: -15469341 | C26: 1779417.3 | D26: -8.6934867 | E26: 4.8252463e-17 | F26: -18965231 | G26: -11973450 | H26: -18965231 | I26: -11973450
A27: Age | B27: 633653.6 | C27: 69030.161 | D27: 9.179373 | E27: 1.0798131e-18 | F27: 498035.13 | G27: 769272.08 | H27: 498035.13 | I27: 769272.08
A28: PTS | B28: 13308.466 | C28: 685.60016 | D28: 19.411411 | E28: 2.9318703e-63 | F28: 11961.518 | G28: 14655.415 | H28: 11961.518 | I28: 14655.415
A30: Interpretations:
A31: R-squared = | B31: =B14 -> 0.50252044 | D31: The r-squared value indicates that our final model explains 50.2% of the variation in average salary for NBA players.
A32: Adj. R-squared = | B32: =B15 -> 0.50056954 | D32: The adjusted r-squared value indicates that our final model explains 50% of the variation in average salary.
A34: Intercept | B34: -15469341 | D34: The intercept indicates that for a hypothetical player with age 0 and 0 total points scored, we predict an average salary of -$15,469,341, holding all other predictors constant.
A35: Age | B35: 633653.6 | D35: For each 1 year increase in player age, we predict an average salary increase of $633,653.60, holding all other predictors constant.
A36: PTS | B36: 13308.466 | D36: For each additional point scored in a player's seasonal total, we predict an average salary increase of $13,308.47, holding all other predictors constant.
A38: Using claude, we learned a couple of things. Firstly, claude flagged our adjusted R-squared interpretation, stating that we should be aware of its difference from R-squared. Part of the adjusted R-squared interpretation
A39: should touch on how it adjusts for using multiple predictors in a model. Additionally, we had initially considered using model 9 as our final model. However, claude helped us with that, and agreed that it'd make more
A40: sense to remove effective field goal % from the model and move forward with a model only containing age and points.
A42: We chose this as our final model because all other variables were either insigificant predictors given their p-values, or in the case of effective field goal %, weren't practically significant.
A43: Age and points are both statistically and practically significant, and the r-squared value remained around 0.5 for the entirety of our backward elimination. In other words, the removal of
A44: all other predictors didn't make our r-squared value any worse.

Sheet Multicollinearity
A1: MULTICOLLINEARITY CHECK
A2: Correlation matrix of all continuous independent variables considered in Model 1. The categorical dummy variables
A3: (Conf_East, Conf_West, Pos_Guard, Pos_Forward) and the dependent variable (SalaryUSD) are excluded from this matrix.
A4: Correlations at or above 0.700 in absolute value are highlighted in yellow.
B6: Age | C6: PTS | D6: STL | E6: AstTovRatio | F6: BLK | G6: TRB | H6: eFG
A7: Age | B7: 1
A8: PTS | B8: =CORREL(Data!$E$2:$E$514,Data!$D$2:$D$514) -> 0.12809876 | C8: 1
A9: STL | B9: =CORREL(Data!$I$2:$I$514,Data!$D$2:$D$514) -> 0.17049323 | C9: =CORREL(Data!$I$2:$I$514,Data!$E$2:$E$514) -> 0.74651388 | D9: 1
A10: AstTovRatio | B10: =CORREL(Data!$J$2:$J$514,Data!$D$2:$D$514) -> 0.20159898 | C10: =CORREL(Data!$J$2:$J$514,Data!$E$2:$E$514) -> 0.12376703 | D10: =CORREL(Data!$J$2:$J$514,Data!$I$2:$I$514) -> 0.28501514 | E10: 1
A11: BLK | B11: =CORREL(Data!$M$2:$M$514,Data!$D$2:$D$514) -> 0.074729439 | C11: =CORREL(Data!$M$2:$M$514,Data!$E$2:$E$514) -> 0.40195066 | D11: =CORREL(Data!$M$2:$M$514,Data!$I$2:$I$514) -> 0.40443887 | E11: =CORREL(Data!$M$2:$M$514,Data!$J$2:$J$514) -> -0.14047371 | F11: 1
A12: TRB | B12: =CORREL(Data!$N$2:$N$514,Data!$D$2:$D$514) -> 0.13261021 | C12: =CORREL(Data!$N$2:$N$514,Data!$E$2:$E$514) -> 0.71765193 | D12: =CORREL(Data!$N$2:$N$514,Data!$I$2:$I$514) -> 0.62575783 | E12: =CORREL(Data!$N$2:$N$514,Data!$J$2:$J$514) -> -0.021913825 | F12: =CORREL(Data!$N$2:$N$514,Data!$M$2:$M$514) -> 0.72340818 | G12: 1
A13: eFG | B13: =CORREL(Data!$P$2:$P$514,Data!$D$2:$D$514) -> 0.16107327 | C13: =CORREL(Data!$P$2:$P$514,Data!$E$2:$E$514) -> 0.26543186 | D13: =CORREL(Data!$P$2:$P$514,Data!$I$2:$I$514) -> 0.21585546 | E13: =CORREL(Data!$P$2:$P$514,Data!$J$2:$J$514) -> -0.033026401 | F13: =CORREL(Data!$P$2:$P$514,Data!$M$2:$M$514) -> 0.32681183 | G13: =CORREL(Data!$P$2:$P$514,Data!$N$2:$N$514) -> 0.34202834 | H13: 1
A15: Correlation of each continuous predictor with the dependent variable (SalaryUSD):
B16: Corr. with SalaryUSD
A17: Age | B17: =CORREL(Data!$F$2:$F$514,Data!$D$2:$D$514) -> 0.36737996
A18: PTS | B18: =CORREL(Data!$F$2:$F$514,Data!$E$2:$E$514) -> 0.64832719
A19: STL | B19: =CORREL(Data!$F$2:$F$514,Data!$I$2:$I$514) -> 0.49477081
A20: AstTovRatio | B20: =CORREL(Data!$F$2:$F$514,Data!$J$2:$J$514) -> 0.14757639
A21: BLK | B21: =CORREL(Data!$F$2:$F$514,Data!$M$2:$M$514) -> 0.27040109
A22: TRB | B22: =CORREL(Data!$F$2:$F$514,Data!$N$2:$N$514) -> 0.46281486
A23: eFG | B23: =CORREL(Data!$F$2:$F$514,Data!$P$2:$P$514) -> 0.14442967
A25: Strong correlations (|r| >= 0.700):
A26: PTS and STL (r = 0.747), BLK and TRB (r = 0.723), and PTS and TRB (r = 0.718) are all strongly correlated. STL and TRB (r = 0.626) is also
A27: moderately strong and worth noting. Every one of these pairs is a season total rather than a rate, so all of them are driven by the same
A28: underlying factor: playing time. A player who is on the floor for heavy minutes accumulates more points, rebounds, steals, and blocks at the
A29: same time, which is exactly why these counting stats move together. Age, AstTovRatio, and eFG are rate or non-volume measures, and none of
A30: them correlate above 0.35 with anything else in the matrix.
A32: Why this matters:
A33: Strong correlations among predictors inflate standard errors, which makes t-statistics smaller and p-values larger. This is very likely what we
A34: were seeing in Models 1 through 8: TRB, STL, and BLK all had large p-values (0.276, 0.659, and 0.312 in Model 1) even though each of them is
A35: positively correlated with salary on its own (0.463, 0.495, and 0.270 in the table above). Their explanatory power was already being captured by
A36: PTS, so they had little unique variation left to explain and looked insignificant as a result. Coefficient signs were also unstable, most obviously
A37: TRB, which was negative in every model despite having a positive simple correlation with salary.
... A50: removed: most of what those predictors explained was already contained in PTS and Age.

Sheet Regression Commentary
A1: REGRESSION COMMENTARY
A3: Final model: Predicted Salary = -15,469,341 + 633,654(Age) + 13,308(PTS)
A5: How the final model performs:
A6: Our final model uses a player's age and total points scored to predict salary, and it explains 50.3% of the variation in NBA salaries
A7: (adjusted R-squared of 50.1%). The overall model is highly significant (F = 257.58, Significance F = 4.76E-78), and both predictors are
A8: significant well beyond the 0.05 level (p = 1.08E-18 for age and p = 2.93E-63 for points). What we found most convincing about this model is
A9: how little we gave up to get there. Model 1 used all eleven predictors and reached an R-squared of 0.511; the final model uses two predictors
A10: and reaches 0.503. Dropping nine variables cost us less than one percentage point of explanatory power, and the adjusted R-squared actually
A11: stayed essentially flat (0.5007 in Model 1 versus 0.5006 here), which tells us the removed variables were not earning their place in the model.
A12: The standard error is still large in absolute terms (about $6.4 million), so the model is much better at describing general salary patterns than
A13: at pinning down what any one specific player will earn.
A15: Interpreting the significant predictors:
... A48: extended to other seasons or to eras under a different collective bargaining agreement without re-fitting the model.
